Traceback (most recent call last):
  File "C:\Users\luuka\Anaconda3\envs\jb1\lib\site-packages\jupyter_cache\executors\utils.py", line 51, in single_nb_execution
    executenb(
  File "C:\Users\luuka\Anaconda3\envs\jb1\lib\site-packages\nbclient\client.py", line 1112, in execute
    return NotebookClient(nb=nb, resources=resources, km=km, **kwargs).execute()
  File "C:\Users\luuka\Anaconda3\envs\jb1\lib\site-packages\nbclient\util.py", line 74, in wrapped
    return just_run(coro(*args, **kwargs))
  File "C:\Users\luuka\Anaconda3\envs\jb1\lib\site-packages\nbclient\util.py", line 53, in just_run
    return loop.run_until_complete(coro)
  File "C:\Users\luuka\Anaconda3\envs\jb1\lib\asyncio\base_events.py", line 642, in run_until_complete
    return future.result()
  File "C:\Users\luuka\Anaconda3\envs\jb1\lib\site-packages\nbclient\client.py", line 553, in async_execute
    await self.async_execute_cell(
  File "C:\Users\luuka\Anaconda3\envs\jb1\lib\site-packages\nbclient\client.py", line 857, in async_execute_cell
    self._check_raise_for_error(cell, exec_reply)
  File "C:\Users\luuka\Anaconda3\envs\jb1\lib\site-packages\nbclient\client.py", line 760, in _check_raise_for_error
    raise CellExecutionError.from_cell_and_msg(cell, exec_reply_content)
nbclient.exceptions.CellExecutionError: An error occurred while executing the following cell:
------------------
import cv2
from google.colab.patches import cv2_imshow
from matplotlib import pyplot as plt
import numpy as np
import imutils
import os
------------------

[1;31m---------------------------------------------------------------------------[0m
[1;31mModuleNotFoundError[0m                       Traceback (most recent call last)
[1;32m~\AppData\Local\Temp/ipykernel_4944/1529994313.py[0m in [0;36m<module>[1;34m[0m
[1;32m----> 1[1;33m [1;32mimport[0m [0mcv2[0m[1;33m[0m[1;33m[0m[0m
[0m[0;32m      2[0m [1;32mfrom[0m [0mgoogle[0m[1;33m.[0m[0mcolab[0m[1;33m.[0m[0mpatches[0m [1;32mimport[0m [0mcv2_imshow[0m[1;33m[0m[1;33m[0m[0m
[0;32m      3[0m [1;32mfrom[0m [0mmatplotlib[0m [1;32mimport[0m [0mpyplot[0m [1;32mas[0m [0mplt[0m[1;33m[0m[1;33m[0m[0m
[0;32m      4[0m [1;32mimport[0m [0mnumpy[0m [1;32mas[0m [0mnp[0m[1;33m[0m[1;33m[0m[0m
[0;32m      5[0m [1;32mimport[0m [0mimutils[0m[1;33m[0m[1;33m[0m[0m

[1;31mModuleNotFoundError[0m: No module named 'cv2'
ModuleNotFoundError: No module named 'cv2'

